<?xml version="1.0" ?>
<robot name="Snowplow_URDF" xmlns:xacro="http://www.ros.org/wiki/xacro">

<xacro:include filename="$(find Snowplow_URDF_description)/urdf/materials.xacro" />
<xacro:include filename="$(find Snowplow_URDF_description)/urdf/Snowplow_URDF.trans" />
<xacro:include filename="$(find Snowplow_URDF_description)/urdf/Snowplow_URDF.gazebo" />
<xacro:include filename="$(find Snowplow_URDF_description)/urdf/lidar_xd.xacro" />
<xacro:sick_lms_1xx name="lidar" ros_topic="scan" />

<link name="base_link">
  <inertial>
    <origin xyz="-0.25586676353018807 0.000039307641348851954 0.2586743162275578" rpy="0 0 0"/>
    <mass value="145.15"/>
    <inertia ixx="4.84425197236" iyy="4.557425293" izz="5.02371818712" iyz="0.0" ixy="0.0" ixz="-0.02161067673"/>
  </inertial>
  <visual>
    <origin xyz="0 0 0" rpy="0 0 0"/>
    <geometry>
      <mesh filename="file://$(find Snowplow_URDF_description)/meshes/base_link.dae" scale="0.001 0.001 0.001"/>
    </geometry>
    <material name="dk_green"/>
  </visual>
  <collision>
    <origin xyz="0 0 0" rpy="0 0 0"/>
    <geometry>
      <mesh filename="file://$(find Snowplow_URDF_description)/meshes/base_link_collision.stl" scale="0.001 0.001 0.001"/>
    </geometry>
  </collision>
</link>

<link name="wheel_fl_1">
  <inertial>
    <origin xyz="-3.730349362740526e-15 0.09077849192803256 -3.83026943495679e-15" rpy="0 0 0"/>
    <mass value="6.80389"/>
    <inertia ixx="0.11749384354" iyy="0.20716716933" izz="0.11749384354" ixy="-0.0" iyz="0.0" ixz="-0.0"/>
  </inertial>
  <visual>
    <origin xyz="0.2902 -0.30635 -0.08255" rpy="0 0 0"/>
    <geometry>
      <mesh filename="file://$(find Snowplow_URDF_description)/meshes/wheel_fl.dae" scale="0.001 0.001 0.001"/>
    </geometry>
    <material name="black"/>
  </visual>
  <collision>
    <origin xyz="0.2902 -0.30635 -0.08255" rpy="0 0 0"/>
    <geometry>
      <mesh filename="file://$(find Snowplow_URDF_description)/meshes/wheel_fl_collision.stl" scale="0.001 0.001 0.001"/>
    </geometry>
  </collision>
</link>

<link name="wheel_fr_1">
  <inertial>
    <origin xyz="3.9968028886505635e-15 -0.09077849192803216 3.730349362740526e-15" rpy="0 0 0"/>
    <mass value="6.80389"/>
    <inertia ixx="0.11749384354" iyy="0.20716716933" izz="0.11749384354" ixy="-0.0" iyz="0.0" ixz="-0.0"/>
  </inertial>
  <visual>
    <origin xyz="0.2902 0.30635 -0.08255" rpy="0 0 0"/>
    <geometry>
      <mesh filename="file://$(find Snowplow_URDF_description)/meshes/wheel_fr.dae" scale="0.001 0.001 0.001"/>
    </geometry>
    <material name="black"/>
  </visual>
  <collision>
    <origin xyz="0.2902 0.30635 -0.08255" rpy="0 0 0"/>
    <geometry>
      <mesh filename="file://$(find Snowplow_URDF_description)/meshes/wheel_fr_collision.stl" scale="0.001 0.001 0.001"/>
    </geometry>
  </collision>
</link>

<link name="wheel_bl_1">
  <inertial>
    <origin xyz="-3.730349362740526e-15 0.09077849192803207 3.808064974464287e-15" rpy="0 0 0"/>
    <mass value="6.80389"/>
    <inertia ixx="0.11749384354" iyy="0.20716716933" izz="0.11749384354" ixy="-0.0" iyz="0.0" ixz="-0.0"/>
  </inertial>
  <visual>
    <origin xyz="1.0289 -0.30635 -0.08255" rpy="0 0 0"/>
    <geometry>
      <mesh filename="file://$(find Snowplow_URDF_description)/meshes/wheel_bl.dae" scale="0.001 0.001 0.001"/>
    </geometry>
    <material name="black"/>
  </visual>
  <collision>
    <origin xyz="1.0289 -0.30635 -0.08255" rpy="0 0 0"/>
    <geometry>
      <mesh filename="file://$(find Snowplow_URDF_description)/meshes/wheel_bl_collision.stl" scale="0.001 0.001 0.001"/>
    </geometry>
  </collision>
</link>

<link name="wheel_br_1">
  <inertial>
    <origin xyz="3.9968028886505635e-15 -0.0907784919280322 -3.785860513971784e-15 " rpy="0 0 0"/>
    <mass value="6.80389"/>
    <inertia ixx="0.11749384354" iyy="0.20716716933" izz="0.11749384354" ixy="-0.0" iyz="0.0" ixz="-0.0"/>
  </inertial>
  <visual>
    <origin xyz="1.0289 0.30635 -0.08255" rpy="0 0 0"/>
    <geometry>
      <mesh filename="file://$(find Snowplow_URDF_description)/meshes/wheel_br.dae" scale="0.001 0.001 0.001"/>
    </geometry>
    <material name="black"/>
  </visual>
  <collision>
    <origin xyz="1.0289 0.30635 -0.08255" rpy="0 0 0"/>
    <geometry>
      <mesh filename="file://$(find Snowplow_URDF_description)/meshes/wheel_br_collision.stl" scale="0.001 0.001 0.001"/>
    </geometry>
  </collision>
</link>


<link name="back_1">
  <inertial>
    <origin xyz="-0.4002194744336831 -2.8073985617496778e-16 0.04900225925646633" rpy="0 0 0"/>
    <mass value="145.15"/>
    <inertia ixx="4.8232327848" iyy="4.53348956976" izz="5.0206133078" ixy="-0.0" iyz="-0.0" ixz="0.03733889251"/>
  </inertial>
  <visual>
    <origin xyz="0.654 -0.0 -0.3051" rpy="0 0 0"/>
    <geometry>
      <mesh filename="file://$(find Snowplow_URDF_description)/meshes/back.dae" scale="0.001 0.001 0.001"/>
    </geometry>
    <material name="dk_green"/>
  </visual>
  <collision>
    <origin xyz="0.654 -0.0 -0.3051" rpy="0 0 0"/>
    <geometry>
      <mesh filename="file://$(find Snowplow_URDF_description)/meshes/back_collision.stl" scale="0.001 0.001 0.001"/>
    </geometry>
  </collision>
</link>

<joint name="wheel_fl_to_base_link" type="continuous">
  <origin xyz="-0.2902 0.30635 0.08255" rpy="0 0 0"/>
  <parent link="base_link"/>
  <child link="wheel_fl_1"/>
  <axis xyz="0.0 1.0 0.0"/>
</joint>

<joint name="wheel_fr_to_base_link" type="continuous">
  <origin xyz="-0.2902 -0.30635 0.08255" rpy="0 0 0"/>
  <parent link="base_link"/>
  <child link="wheel_fr_1"/>
  <axis xyz="0.0 -1.0 0.0"/>
</joint>

<joint name="wheel_bl_to_back" type="continuous">
  <origin xyz="-0.3638 0.30635 -0.22255" rpy="0 0 0"/>
  <parent link="back_1"/>
  <child link="wheel_bl_1"/>
  <axis xyz="0.0 1.0 0.0"/>
</joint>

<joint name="wheel_br_to_back" type="continuous">
  <origin xyz="-0.3638 -0.30635 -0.22255" rpy="0 0 0"/>
  <parent link="back_1"/>
  <child link="wheel_br_1"/>
  <axis xyz="0.0 -1.0 0.0"/>
</joint>

<joint name="back_to_base_link" type="revolute">
  <origin xyz="-0.654 0.0 0.3051" rpy="0 0 0"/>
  <parent link="base_link"/>
  <child link="back_1"/>
  <axis xyz="0.0 0.0 1.0"/>
  <limit effort="1000" velocity="2.0" lower="-0.6" upper="0.6" />
</joint>

</robot>
